[2024-05-25 14:50:41] [WARNING ] discord.client: PyNaCl is not installed, voice will NOT be supported
[2024-05-25 14:50:41] [INFO    ] discord.client: logging in using static token
[2024-05-25 14:51:11] [WARNING ] discord.client: PyNaCl is not installed, voice will NOT be supported
[2024-05-25 14:51:11] [INFO    ] discord.client: logging in using static token
[2024-05-25 14:51:15] [INFO    ] discord.gateway: Shard ID None has connected to Gateway (Session ID: 2f8919544a11363652f72fe4f11f6f73).
[2024-05-25 14:56:28] [WARNING ] discord.client: PyNaCl is not installed, voice will NOT be supported
[2024-05-25 14:56:28] [INFO    ] discord.client: logging in using static token
[2024-05-25 14:56:30] [INFO    ] discord.gateway: Shard ID None has connected to Gateway (Session ID: 1a6df70c3a9e2a700858ef00645af2c5).
[2024-06-14 20:44:28] [WARNING ] discord.client: PyNaCl is not installed, voice will NOT be supported
[2024-06-14 20:44:28] [INFO    ] discord.client: logging in using static token
[2024-06-14 20:44:30] [INFO    ] discord.gateway: Shard ID None has connected to Gateway (Session ID: 53c09742a8ec7d9502c81422b583078e).
[2024-06-14 21:08:09] [WARNING ] discord.client: PyNaCl is not installed, voice will NOT be supported
[2024-06-14 21:08:09] [INFO    ] discord.client: logging in using static token
[2024-06-14 21:08:12] [INFO    ] discord.gateway: Shard ID None has connected to Gateway (Session ID: 0308a65a6d06e2d8d9bfc07af4d936ef).
[2024-06-14 21:14:50] [WARNING ] discord.client: PyNaCl is not installed, voice will NOT be supported
[2024-06-14 21:14:50] [INFO    ] discord.client: logging in using static token
[2024-06-14 21:15:34] [INFO    ] discord.gateway: Shard ID None has connected to Gateway (Session ID: 6b15aebccd37a290993b4f6faa9cd839).
[2024-06-14 21:18:14] [WARNING ] discord.client: PyNaCl is not installed, voice will NOT be supported
[2024-06-14 21:18:14] [INFO    ] discord.client: logging in using static token
[2024-06-14 21:18:16] [INFO    ] discord.gateway: Shard ID None has connected to Gateway (Session ID: db8acb96780bbb07308dadf93b5dfd38).
[2024-06-14 21:19:30] [ERROR   ] discord.client: Ignoring exception in on_user_update
Traceback (most recent call last):
  File "C:\Users\razzies\AppData\Local\Programs\Python\Python312\Lib\site-packages\discord\client.py", line 441, in _run_event
    await coro(*args, **kwargs)
  File "D:\Projects\avatar logger\bot\cogs\event.py", line 35, in on_user_update
    await channel.send(f"{after.mention} | `{after.name}` | `{after.id}` | <t:{int(time.time())}:R>", file=discord.File(f"{avatar_path}{fname}", fname))
                                                                                                           ^^^^^^^^^^^^^^^^^^^^^^^^^^^^^^^^^^^^^^^^^^^^
  File "C:\Users\razzies\AppData\Local\Programs\Python\Python312\Lib\site-packages\discord\file.py", line 97, in __init__
    self.fp = open(fp, 'rb')
              ^^^^^^^^^^^^^^
FileNotFoundError: [Errno 2] No such file or directory: 'D:\\Projects\\avatar logger\\webui\\static\\avatars\\5785856239219507402024-06-14_21-19-29.ymtnfmsutp.png'
[2024-06-14 21:19:39] [ERROR   ] discord.client: Ignoring exception in on_user_update
Traceback (most recent call last):
  File "C:\Users\razzies\AppData\Local\Programs\Python\Python312\Lib\site-packages\discord\client.py", line 441, in _run_event
    await coro(*args, **kwargs)
  File "D:\Projects\avatar logger\bot\cogs\event.py", line 35, in on_user_update
    await channel.send(f"{after.mention} | `{after.name}` | `{after.id}` | <t:{int(time.time())}:R>", file=discord.File(f"{avatar_path}{fname}", fname))
                                                                                                           ^^^^^^^^^^^^^^^^^^^^^^^^^^^^^^^^^^^^^^^^^^^^
  File "C:\Users\razzies\AppData\Local\Programs\Python\Python312\Lib\site-packages\discord\file.py", line 97, in __init__
    self.fp = open(fp, 'rb')
              ^^^^^^^^^^^^^^
FileNotFoundError: [Errno 2] No such file or directory: 'D:\\Projects\\avatar logger\\webui\\static\\avatars\\11521739515276985422024-06-14_21-19-38.tjlqbvvygi.png'
[2024-06-14 21:20:16] [WARNING ] discord.client: PyNaCl is not installed, voice will NOT be supported
[2024-06-14 21:20:16] [INFO    ] discord.client: logging in using static token
[2024-06-14 21:20:19] [INFO    ] discord.gateway: Shard ID None has connected to Gateway (Session ID: f641bd4d6203e153bf4016cc01d4756c).
[2024-06-14 21:24:14] [ERROR   ] discord.client: Ignoring exception in on_user_update
Traceback (most recent call last):
  File "C:\Users\razzies\AppData\Local\Programs\Python\Python312\Lib\site-packages\discord\client.py", line 441, in _run_event
    await coro(*args, **kwargs)
  File "D:\Projects\avatar logger\bot\cogs\event.py", line 35, in on_user_update
    await channel.send(f"{after.mention} | `{after.name}` | `{after.id}` | <t:{int(time.time())}:R>", file=discord.File(f"{avatar_path}{fname}", fname))
                                                                                                           ^^^^^^^^^^^^^^^^^^^^^^^^^^^^^^^^^^^^^^^^^^^^
  File "C:\Users\razzies\AppData\Local\Programs\Python\Python312\Lib\site-packages\discord\file.py", line 97, in __init__
    self.fp = open(fp, 'rb')
              ^^^^^^^^^^^^^^
FileNotFoundError: [Errno 2] No such file or directory: 'D:\\Projects\\avatar logger\\webui\\static\\avatars\\9285052409893397092024-06-14_21-24-13.ljzydgokxt.png'
[2024-06-14 21:26:01] [ERROR   ] discord.client: Ignoring exception in on_user_update
Traceback (most recent call last):
  File "C:\Users\razzies\AppData\Local\Programs\Python\Python312\Lib\site-packages\discord\client.py", line 441, in _run_event
    await coro(*args, **kwargs)
  File "D:\Projects\avatar logger\bot\cogs\event.py", line 35, in on_user_update
    await channel.send(f"{after.mention} | `{after.name}` | `{after.id}` | <t:{int(time.time())}:R>", file=discord.File(f"{avatar_path}{fname}", fname))
                                                                                                           ^^^^^^^^^^^^^^^^^^^^^^^^^^^^^^^^^^^^^^^^^^^^
  File "C:\Users\razzies\AppData\Local\Programs\Python\Python312\Lib\site-packages\discord\file.py", line 97, in __init__
    self.fp = open(fp, 'rb')
              ^^^^^^^^^^^^^^
FileNotFoundError: [Errno 2] No such file or directory: 'D:\\Projects\\avatar logger\\webui\\static\\avatars\\12211664107853619912024-06-14_21-26-01.sziqydbrfp.png'
[2024-06-14 21:26:37] [ERROR   ] discord.client: Ignoring exception in on_user_update
Traceback (most recent call last):
  File "C:\Users\razzies\AppData\Local\Programs\Python\Python312\Lib\site-packages\discord\client.py", line 441, in _run_event
    await coro(*args, **kwargs)
  File "D:\Projects\avatar logger\bot\cogs\event.py", line 35, in on_user_update
    await channel.send(f"{after.mention} | `{after.name}` | `{after.id}` | <t:{int(time.time())}:R>", file=discord.File(f"{avatar_path}{fname}", fname))
                                                                                                           ^^^^^^^^^^^^^^^^^^^^^^^^^^^^^^^^^^^^^^^^^^^^
  File "C:\Users\razzies\AppData\Local\Programs\Python\Python312\Lib\site-packages\discord\file.py", line 97, in __init__
    self.fp = open(fp, 'rb')
              ^^^^^^^^^^^^^^
FileNotFoundError: [Errno 2] No such file or directory: 'D:\\Projects\\avatar logger\\webui\\static\\avatars\\7090545711078441682024-06-14_21-26-36.ikwzuuhcpq.png'
[2024-06-14 21:27:18] [ERROR   ] discord.client: Ignoring exception in on_user_update
Traceback (most recent call last):
  File "C:\Users\razzies\AppData\Local\Programs\Python\Python312\Lib\site-packages\discord\client.py", line 441, in _run_event
    await coro(*args, **kwargs)
  File "D:\Projects\avatar logger\bot\cogs\event.py", line 35, in on_user_update
    await channel.send(f"{after.mention} | `{after.name}` | `{after.id}` | <t:{int(time.time())}:R>", file=discord.File(f"{avatar_path}{fname}", fname))
                                                                                                           ^^^^^^^^^^^^^^^^^^^^^^^^^^^^^^^^^^^^^^^^^^^^
  File "C:\Users\razzies\AppData\Local\Programs\Python\Python312\Lib\site-packages\discord\file.py", line 97, in __init__
    self.fp = open(fp, 'rb')
              ^^^^^^^^^^^^^^
FileNotFoundError: [Errno 2] No such file or directory: 'D:\\Projects\\avatar logger\\webui\\static\\avatars\\10001457227395400082024-06-14_21-27-18.ygdnraghhy.png'
[2024-06-14 21:29:35] [ERROR   ] discord.client: Ignoring exception in on_user_update
Traceback (most recent call last):
  File "C:\Users\razzies\AppData\Local\Programs\Python\Python312\Lib\site-packages\discord\client.py", line 441, in _run_event
    await coro(*args, **kwargs)
  File "D:\Projects\avatar logger\bot\cogs\event.py", line 35, in on_user_update
    await channel.send(f"{after.mention} | `{after.name}` | `{after.id}` | <t:{int(time.time())}:R>", file=discord.File(f"{avatar_path}{fname}", fname))
                                                                                                           ^^^^^^^^^^^^^^^^^^^^^^^^^^^^^^^^^^^^^^^^^^^^
  File "C:\Users\razzies\AppData\Local\Programs\Python\Python312\Lib\site-packages\discord\file.py", line 97, in __init__
    self.fp = open(fp, 'rb')
              ^^^^^^^^^^^^^^
FileNotFoundError: [Errno 2] No such file or directory: 'D:\\Projects\\avatar logger\\webui\\static\\avatars\\7566458411876352322024-06-14_21-29-35.nguuttyekz.png'
[2024-06-14 21:29:49] [ERROR   ] discord.client: Ignoring exception in on_user_update
Traceback (most recent call last):
  File "C:\Users\razzies\AppData\Local\Programs\Python\Python312\Lib\site-packages\discord\client.py", line 441, in _run_event
    await coro(*args, **kwargs)
  File "D:\Projects\avatar logger\bot\cogs\event.py", line 35, in on_user_update
    await channel.send(f"{after.mention} | `{after.name}` | `{after.id}` | <t:{int(time.time())}:R>", file=discord.File(f"{avatar_path}{fname}", fname))
                                                                                                           ^^^^^^^^^^^^^^^^^^^^^^^^^^^^^^^^^^^^^^^^^^^^
  File "C:\Users\razzies\AppData\Local\Programs\Python\Python312\Lib\site-packages\discord\file.py", line 97, in __init__
    self.fp = open(fp, 'rb')
              ^^^^^^^^^^^^^^
FileNotFoundError: [Errno 2] No such file or directory: 'D:\\Projects\\avatar logger\\webui\\static\\avatars\\7566458411876352322024-06-14_21-29-49.xrazkagpcb.png'
[2024-06-14 21:31:40] [ERROR   ] discord.client: Ignoring exception in on_user_update
Traceback (most recent call last):
  File "C:\Users\razzies\AppData\Local\Programs\Python\Python312\Lib\site-packages\discord\client.py", line 441, in _run_event
    await coro(*args, **kwargs)
  File "D:\Projects\avatar logger\bot\cogs\event.py", line 35, in on_user_update
    await channel.send(f"{after.mention} | `{after.name}` | `{after.id}` | <t:{int(time.time())}:R>", file=discord.File(f"{avatar_path}{fname}", fname))
                                                                                                           ^^^^^^^^^^^^^^^^^^^^^^^^^^^^^^^^^^^^^^^^^^^^
  File "C:\Users\razzies\AppData\Local\Programs\Python\Python312\Lib\site-packages\discord\file.py", line 97, in __init__
    self.fp = open(fp, 'rb')
              ^^^^^^^^^^^^^^
FileNotFoundError: [Errno 2] No such file or directory: 'D:\\Projects\\avatar logger\\webui\\static\\avatars\\8156555778532311552024-06-14_21-31-40.qkgjcrtyga.png'
[2024-06-14 21:32:55] [INFO    ] discord.gateway: Shard ID None has successfully RESUMED session f641bd4d6203e153bf4016cc01d4756c.
[2024-06-14 21:35:49] [ERROR   ] discord.client: Ignoring exception in on_user_update
Traceback (most recent call last):
  File "C:\Users\razzies\AppData\Local\Programs\Python\Python312\Lib\site-packages\discord\client.py", line 441, in _run_event
    await coro(*args, **kwargs)
  File "D:\Projects\avatar logger\bot\cogs\event.py", line 35, in on_user_update
    await channel.send(f"{after.mention} | `{after.name}` | `{after.id}` | <t:{int(time.time())}:R>", file=discord.File(f"{avatar_path}{fname}", fname))
                                                                                                           ^^^^^^^^^^^^^^^^^^^^^^^^^^^^^^^^^^^^^^^^^^^^
  File "C:\Users\razzies\AppData\Local\Programs\Python\Python312\Lib\site-packages\discord\file.py", line 97, in __init__
    self.fp = open(fp, 'rb')
              ^^^^^^^^^^^^^^
FileNotFoundError: [Errno 2] No such file or directory: 'D:\\Projects\\avatar logger\\webui\\static\\avatars\\9791229220294820042024-06-14_21-35-49.fdrxwtldsk.png'
[2024-06-14 21:37:30] [ERROR   ] discord.client: Ignoring exception in on_user_update
Traceback (most recent call last):
  File "C:\Users\razzies\AppData\Local\Programs\Python\Python312\Lib\site-packages\discord\client.py", line 441, in _run_event
    await coro(*args, **kwargs)
  File "D:\Projects\avatar logger\bot\cogs\event.py", line 35, in on_user_update
    await channel.send(f"{after.mention} | `{after.name}` | `{after.id}` | <t:{int(time.time())}:R>", file=discord.File(f"{avatar_path}{fname}", fname))
                                                                                                           ^^^^^^^^^^^^^^^^^^^^^^^^^^^^^^^^^^^^^^^^^^^^
  File "C:\Users\razzies\AppData\Local\Programs\Python\Python312\Lib\site-packages\discord\file.py", line 97, in __init__
    self.fp = open(fp, 'rb')
              ^^^^^^^^^^^^^^
FileNotFoundError: [Errno 2] No such file or directory: 'D:\\Projects\\avatar logger\\webui\\static\\avatars\\9291216739307397732024-06-14_21-37-30.uxskyszqyf.png'
[2024-06-14 21:38:06] [ERROR   ] discord.client: Ignoring exception in on_user_update
Traceback (most recent call last):
  File "C:\Users\razzies\AppData\Local\Programs\Python\Python312\Lib\site-packages\discord\client.py", line 441, in _run_event
    await coro(*args, **kwargs)
  File "D:\Projects\avatar logger\bot\cogs\event.py", line 35, in on_user_update
    await channel.send(f"{after.mention} | `{after.name}` | `{after.id}` | <t:{int(time.time())}:R>", file=discord.File(f"{avatar_path}{fname}", fname))
                                                                                                           ^^^^^^^^^^^^^^^^^^^^^^^^^^^^^^^^^^^^^^^^^^^^
  File "C:\Users\razzies\AppData\Local\Programs\Python\Python312\Lib\site-packages\discord\file.py", line 97, in __init__
    self.fp = open(fp, 'rb')
              ^^^^^^^^^^^^^^
FileNotFoundError: [Errno 2] No such file or directory: 'D:\\Projects\\avatar logger\\webui\\static\\avatars\\9291216739307397732024-06-14_21-38-06.smyvxjjrhj.png'
[2024-06-14 21:39:59] [WARNING ] discord.client: PyNaCl is not installed, voice will NOT be supported
[2024-06-14 21:40:00] [INFO    ] discord.client: logging in using static token
[2024-06-14 21:40:02] [INFO    ] discord.gateway: Shard ID None has connected to Gateway (Session ID: a0c6d027695748df7dea54f8f72833ed).
[2024-06-14 21:41:37] [ERROR   ] discord.client: Ignoring exception in on_user_update
Traceback (most recent call last):
  File "C:\Users\razzies\AppData\Local\Programs\Python\Python312\Lib\site-packages\discord\client.py", line 441, in _run_event
    await coro(*args, **kwargs)
  File "D:\Projects\avatar logger\bot\cogs\event.py", line 35, in on_user_update
    await channel.send(f"{after.mention} | `{after.name}` | `{after.id}` | <t:{int(time.time())}:R>", file=discord.File(f"{avatar_path}{fname}", fname))
                                                                                                           ^^^^^^^^^^^^^^^^^^^^^^^^^^^^^^^^^^^^^^^^^^^^
  File "C:\Users\razzies\AppData\Local\Programs\Python\Python312\Lib\site-packages\discord\file.py", line 97, in __init__
    self.fp = open(fp, 'rb')
              ^^^^^^^^^^^^^^
FileNotFoundError: [Errno 2] No such file or directory: 'D:\\Projects\\avatar logger\\webui\\static\\avatars\\8519529781268316562024-06-14_21-41-36.mxqwpjzkij.png'
[2024-06-14 21:42:56] [ERROR   ] discord.client: Ignoring exception in on_user_update
Traceback (most recent call last):
  File "C:\Users\razzies\AppData\Local\Programs\Python\Python312\Lib\site-packages\discord\client.py", line 441, in _run_event
    await coro(*args, **kwargs)
  File "D:\Projects\avatar logger\bot\cogs\event.py", line 35, in on_user_update
    await channel.send(f"{after.mention} | `{after.name}` | `{after.id}` | <t:{int(time.time())}:R>", file=discord.File(f"{avatar_path}{fname}", fname))
                                                                                                           ^^^^^^^^^^^^^^^^^^^^^^^^^^^^^^^^^^^^^^^^^^^^
  File "C:\Users\razzies\AppData\Local\Programs\Python\Python312\Lib\site-packages\discord\file.py", line 97, in __init__
    self.fp = open(fp, 'rb')
              ^^^^^^^^^^^^^^
FileNotFoundError: [Errno 2] No such file or directory: 'D:\\Projects\\avatar logger\\webui\\static\\avatars\\7109074424559043062024-06-14_21-42-56.dapkzhhxeu.png'
[2024-06-14 21:44:17] [ERROR   ] discord.client: Ignoring exception in on_user_update
Traceback (most recent call last):
  File "C:\Users\razzies\AppData\Local\Programs\Python\Python312\Lib\site-packages\discord\client.py", line 441, in _run_event
    await coro(*args, **kwargs)
  File "D:\Projects\avatar logger\bot\cogs\event.py", line 35, in on_user_update
    await channel.send(f"{after.mention} | `{after.name}` | `{after.id}` | <t:{int(time.time())}:R>", file=discord.File(f"{avatar_path}{fname}", fname))
                                                                                                           ^^^^^^^^^^^^^^^^^^^^^^^^^^^^^^^^^^^^^^^^^^^^
  File "C:\Users\razzies\AppData\Local\Programs\Python\Python312\Lib\site-packages\discord\file.py", line 97, in __init__
    self.fp = open(fp, 'rb')
              ^^^^^^^^^^^^^^
FileNotFoundError: [Errno 2] No such file or directory: 'D:\\Projects\\avatar logger\\webui\\static\\avatars\\7540241447056834672024-06-14_21-44-16.tcvdquoolg.png'
[2024-06-14 21:49:24] [ERROR   ] discord.client: Ignoring exception in on_user_update
Traceback (most recent call last):
  File "C:\Users\razzies\AppData\Local\Programs\Python\Python312\Lib\site-packages\discord\client.py", line 441, in _run_event
    await coro(*args, **kwargs)
  File "D:\Projects\avatar logger\bot\cogs\event.py", line 35, in on_user_update
    await channel.send(f"{after.mention} | `{after.name}` | `{after.id}` | <t:{int(time.time())}:R>", file=discord.File(f"{avatar_path}{fname}", fname))
                                                                                                           ^^^^^^^^^^^^^^^^^^^^^^^^^^^^^^^^^^^^^^^^^^^^
  File "C:\Users\razzies\AppData\Local\Programs\Python\Python312\Lib\site-packages\discord\file.py", line 97, in __init__
    self.fp = open(fp, 'rb')
              ^^^^^^^^^^^^^^
FileNotFoundError: [Errno 2] No such file or directory: 'D:\\Projects\\avatar logger\\webui\\static\\avatars\\11620337783744922202024-06-14_21-49-23.gjwwisoqxe.png'
[2024-06-14 21:50:03] [ERROR   ] discord.client: Ignoring exception in on_user_update
Traceback (most recent call last):
  File "C:\Users\razzies\AppData\Local\Programs\Python\Python312\Lib\site-packages\discord\client.py", line 441, in _run_event
    await coro(*args, **kwargs)
  File "D:\Projects\avatar logger\bot\cogs\event.py", line 35, in on_user_update
    await channel.send(f"{after.mention} | `{after.name}` | `{after.id}` | <t:{int(time.time())}:R>", file=discord.File(f"{avatar_path}{fname}", fname))
                                                                                                           ^^^^^^^^^^^^^^^^^^^^^^^^^^^^^^^^^^^^^^^^^^^^
  File "C:\Users\razzies\AppData\Local\Programs\Python\Python312\Lib\site-packages\discord\file.py", line 97, in __init__
    self.fp = open(fp, 'rb')
              ^^^^^^^^^^^^^^
FileNotFoundError: [Errno 2] No such file or directory: 'D:\\Projects\\avatar logger\\webui\\static\\avatars\\8410489706999972542024-06-14_21-50-02.gauzyrvjhy.png'
[2024-06-14 21:50:27] [ERROR   ] discord.client: Ignoring exception in on_user_update
Traceback (most recent call last):
  File "C:\Users\razzies\AppData\Local\Programs\Python\Python312\Lib\site-packages\discord\client.py", line 441, in _run_event
    await coro(*args, **kwargs)
  File "D:\Projects\avatar logger\bot\cogs\event.py", line 35, in on_user_update
    await channel.send(f"{after.mention} | `{after.name}` | `{after.id}` | <t:{int(time.time())}:R>", file=discord.File(f"{avatar_path}{fname}", fname))
                                                                                                           ^^^^^^^^^^^^^^^^^^^^^^^^^^^^^^^^^^^^^^^^^^^^
  File "C:\Users\razzies\AppData\Local\Programs\Python\Python312\Lib\site-packages\discord\file.py", line 97, in __init__
    self.fp = open(fp, 'rb')
              ^^^^^^^^^^^^^^
FileNotFoundError: [Errno 2] No such file or directory: 'D:\\Projects\\avatar logger\\webui\\static\\avatars\\11954088062812202662024-06-14_21-50-27.drrkdzmpjl.png'
[2024-06-14 21:52:37] [ERROR   ] discord.client: Ignoring exception in on_user_update
Traceback (most recent call last):
  File "C:\Users\razzies\AppData\Local\Programs\Python\Python312\Lib\site-packages\discord\client.py", line 441, in _run_event
    await coro(*args, **kwargs)
  File "D:\Projects\avatar logger\bot\cogs\event.py", line 35, in on_user_update
    await channel.send(f"{after.mention} | `{after.name}` | `{after.id}` | <t:{int(time.time())}:R>", file=discord.File(f"{avatar_path}{fname}", fname))
                                                                                                           ^^^^^^^^^^^^^^^^^^^^^^^^^^^^^^^^^^^^^^^^^^^^
  File "C:\Users\razzies\AppData\Local\Programs\Python\Python312\Lib\site-packages\discord\file.py", line 97, in __init__
    self.fp = open(fp, 'rb')
              ^^^^^^^^^^^^^^
FileNotFoundError: [Errno 2] No such file or directory: 'D:\\Projects\\avatar logger\\webui\\static\\avatars\\8410489706999972542024-06-14_21-52-36.eqaakcdsmo.png'
[2024-06-14 21:54:05] [ERROR   ] discord.client: Ignoring exception in on_user_update
Traceback (most recent call last):
  File "C:\Users\razzies\AppData\Local\Programs\Python\Python312\Lib\site-packages\discord\client.py", line 441, in _run_event
    await coro(*args, **kwargs)
  File "D:\Projects\avatar logger\bot\cogs\event.py", line 35, in on_user_update
    await channel.send(f"{after.mention} | `{after.name}` | `{after.id}` | <t:{int(time.time())}:R>", file=discord.File(f"{avatar_path}{fname}", fname))
                                                                                                           ^^^^^^^^^^^^^^^^^^^^^^^^^^^^^^^^^^^^^^^^^^^^
  File "C:\Users\razzies\AppData\Local\Programs\Python\Python312\Lib\site-packages\discord\file.py", line 97, in __init__
    self.fp = open(fp, 'rb')
              ^^^^^^^^^^^^^^
FileNotFoundError: [Errno 2] No such file or directory: 'D:\\Projects\\avatar logger\\webui\\static\\avatars\\9730654540987187512024-06-14_21-54-05.nssnqnkobt.png'
[2024-06-14 21:54:11] [ERROR   ] discord.client: Ignoring exception in on_user_update
Traceback (most recent call last):
  File "C:\Users\razzies\AppData\Local\Programs\Python\Python312\Lib\site-packages\discord\client.py", line 441, in _run_event
    await coro(*args, **kwargs)
  File "D:\Projects\avatar logger\bot\cogs\event.py", line 35, in on_user_update
    await channel.send(f"{after.mention} | `{after.name}` | `{after.id}` | <t:{int(time.time())}:R>", file=discord.File(f"{avatar_path}{fname}", fname))
                                                                                                           ^^^^^^^^^^^^^^^^^^^^^^^^^^^^^^^^^^^^^^^^^^^^
  File "C:\Users\razzies\AppData\Local\Programs\Python\Python312\Lib\site-packages\discord\file.py", line 97, in __init__
    self.fp = open(fp, 'rb')
              ^^^^^^^^^^^^^^
FileNotFoundError: [Errno 2] No such file or directory: 'D:\\Projects\\avatar logger\\webui\\static\\avatars\\8410489706999972542024-06-14_21-54-09.pumsrxkgut.png'
[2024-06-14 21:54:13] [ERROR   ] discord.client: Ignoring exception in on_user_update
Traceback (most recent call last):
  File "C:\Users\razzies\AppData\Local\Programs\Python\Python312\Lib\site-packages\discord\client.py", line 441, in _run_event
    await coro(*args, **kwargs)
  File "D:\Projects\avatar logger\bot\cogs\event.py", line 35, in on_user_update
    await channel.send(f"{after.mention} | `{after.name}` | `{after.id}` | <t:{int(time.time())}:R>", file=discord.File(f"{avatar_path}{fname}", fname))
                                                                                                           ^^^^^^^^^^^^^^^^^^^^^^^^^^^^^^^^^^^^^^^^^^^^
  File "C:\Users\razzies\AppData\Local\Programs\Python\Python312\Lib\site-packages\discord\file.py", line 97, in __init__
    self.fp = open(fp, 'rb')
              ^^^^^^^^^^^^^^
FileNotFoundError: [Errno 2] No such file or directory: 'D:\\Projects\\avatar logger\\webui\\static\\avatars\\11954088062812202662024-06-14_21-54-12.mppfgewcjf.png'
[2024-06-14 21:54:40] [ERROR   ] discord.client: Ignoring exception in on_user_update
Traceback (most recent call last):
  File "C:\Users\razzies\AppData\Local\Programs\Python\Python312\Lib\site-packages\discord\client.py", line 441, in _run_event
    await coro(*args, **kwargs)
  File "D:\Projects\avatar logger\bot\cogs\event.py", line 35, in on_user_update
    await channel.send(f"{after.mention} | `{after.name}` | `{after.id}` | <t:{int(time.time())}:R>", file=discord.File(f"{avatar_path}{fname}", fname))
                                                                                                           ^^^^^^^^^^^^^^^^^^^^^^^^^^^^^^^^^^^^^^^^^^^^
  File "C:\Users\razzies\AppData\Local\Programs\Python\Python312\Lib\site-packages\discord\file.py", line 97, in __init__
    self.fp = open(fp, 'rb')
              ^^^^^^^^^^^^^^
FileNotFoundError: [Errno 2] No such file or directory: 'D:\\Projects\\avatar logger\\webui\\static\\avatars\\11507915705603891602024-06-14_21-54-40.cwnupjvnop.png'
[2024-06-14 21:54:57] [ERROR   ] discord.client: Ignoring exception in on_user_update
Traceback (most recent call last):
  File "C:\Users\razzies\AppData\Local\Programs\Python\Python312\Lib\site-packages\discord\client.py", line 441, in _run_event
    await coro(*args, **kwargs)
  File "D:\Projects\avatar logger\bot\cogs\event.py", line 35, in on_user_update
    await channel.send(f"{after.mention} | `{after.name}` | `{after.id}` | <t:{int(time.time())}:R>", file=discord.File(f"{avatar_path}{fname}", fname))
                                                                                                           ^^^^^^^^^^^^^^^^^^^^^^^^^^^^^^^^^^^^^^^^^^^^
  File "C:\Users\razzies\AppData\Local\Programs\Python\Python312\Lib\site-packages\discord\file.py", line 97, in __init__
    self.fp = open(fp, 'rb')
              ^^^^^^^^^^^^^^
FileNotFoundError: [Errno 2] No such file or directory: 'D:\\Projects\\avatar logger\\webui\\static\\avatars\\11954088062812202662024-06-14_21-54-57.ghjxxpduam.png'
[2024-06-14 21:55:31] [ERROR   ] discord.client: Ignoring exception in on_user_update
Traceback (most recent call last):
  File "C:\Users\razzies\AppData\Local\Programs\Python\Python312\Lib\site-packages\discord\client.py", line 441, in _run_event
    await coro(*args, **kwargs)
  File "D:\Projects\avatar logger\bot\cogs\event.py", line 35, in on_user_update
    await channel.send(f"{after.mention} | `{after.name}` | `{after.id}` | <t:{int(time.time())}:R>", file=discord.File(f"{avatar_path}{fname}", fname))
                                                                                                           ^^^^^^^^^^^^^^^^^^^^^^^^^^^^^^^^^^^^^^^^^^^^
  File "C:\Users\razzies\AppData\Local\Programs\Python\Python312\Lib\site-packages\discord\file.py", line 97, in __init__
    self.fp = open(fp, 'rb')
              ^^^^^^^^^^^^^^
FileNotFoundError: [Errno 2] No such file or directory: 'D:\\Projects\\avatar logger\\webui\\static\\avatars\\7878109241908920432024-06-14_21-55-31.cugxaozpbg.png'
[2024-06-14 21:56:32] [ERROR   ] discord.client: Ignoring exception in on_user_update
Traceback (most recent call last):
  File "C:\Users\razzies\AppData\Local\Programs\Python\Python312\Lib\site-packages\discord\client.py", line 441, in _run_event
    await coro(*args, **kwargs)
  File "D:\Projects\avatar logger\bot\cogs\event.py", line 35, in on_user_update
    await channel.send(f"{after.mention} | `{after.name}` | `{after.id}` | <t:{int(time.time())}:R>", file=discord.File(f"{avatar_path}{fname}", fname))
                                                                                                           ^^^^^^^^^^^^^^^^^^^^^^^^^^^^^^^^^^^^^^^^^^^^
  File "C:\Users\razzies\AppData\Local\Programs\Python\Python312\Lib\site-packages\discord\file.py", line 97, in __init__
    self.fp = open(fp, 'rb')
              ^^^^^^^^^^^^^^
FileNotFoundError: [Errno 2] No such file or directory: 'D:\\Projects\\avatar logger\\webui\\static\\avatars\\5405123820158976002024-06-14_21-56-31.enmsniepwp.png'
[2024-06-14 21:58:10] [ERROR   ] discord.client: Ignoring exception in on_user_update
Traceback (most recent call last):
  File "C:\Users\razzies\AppData\Local\Programs\Python\Python312\Lib\site-packages\discord\client.py", line 441, in _run_event
    await coro(*args, **kwargs)
  File "D:\Projects\avatar logger\bot\cogs\event.py", line 35, in on_user_update
    await channel.send(f"{after.mention} | `{after.name}` | `{after.id}` | <t:{int(time.time())}:R>", file=discord.File(f"{avatar_path}{fname}", fname))
                                                                                                           ^^^^^^^^^^^^^^^^^^^^^^^^^^^^^^^^^^^^^^^^^^^^
  File "C:\Users\razzies\AppData\Local\Programs\Python\Python312\Lib\site-packages\discord\file.py", line 97, in __init__
    self.fp = open(fp, 'rb')
              ^^^^^^^^^^^^^^
FileNotFoundError: [Errno 2] No such file or directory: 'D:\\Projects\\avatar logger\\webui\\static\\avatars\\8410489706999972542024-06-14_21-58-08.zmwpqflqpk.png'
[2024-06-14 22:00:12] [ERROR   ] discord.client: Ignoring exception in on_user_update
Traceback (most recent call last):
  File "C:\Users\razzies\AppData\Local\Programs\Python\Python312\Lib\site-packages\discord\client.py", line 441, in _run_event
    await coro(*args, **kwargs)
  File "D:\Projects\avatar logger\bot\cogs\event.py", line 35, in on_user_update
    await channel.send(f"{after.mention} | `{after.name}` | `{after.id}` | <t:{int(time.time())}:R>", file=discord.File(f"{avatar_path}{fname}", fname))
                                                                                                           ^^^^^^^^^^^^^^^^^^^^^^^^^^^^^^^^^^^^^^^^^^^^
  File "C:\Users\razzies\AppData\Local\Programs\Python\Python312\Lib\site-packages\discord\file.py", line 97, in __init__
    self.fp = open(fp, 'rb')
              ^^^^^^^^^^^^^^
FileNotFoundError: [Errno 2] No such file or directory: 'D:\\Projects\\avatar logger\\webui\\static\\avatars\\3562682356975534092024-06-14_22-00-10.mzlbncbbpe.png'
[2024-06-14 22:03:27] [ERROR   ] discord.client: Ignoring exception in on_user_update
Traceback (most recent call last):
  File "C:\Users\razzies\AppData\Local\Programs\Python\Python312\Lib\site-packages\discord\client.py", line 441, in _run_event
    await coro(*args, **kwargs)
  File "D:\Projects\avatar logger\bot\cogs\event.py", line 35, in on_user_update
    await channel.send(f"{after.mention} | `{after.name}` | `{after.id}` | <t:{int(time.time())}:R>", file=discord.File(f"{avatar_path}{fname}", fname))
                                                                                                           ^^^^^^^^^^^^^^^^^^^^^^^^^^^^^^^^^^^^^^^^^^^^
  File "C:\Users\razzies\AppData\Local\Programs\Python\Python312\Lib\site-packages\discord\file.py", line 97, in __init__
    self.fp = open(fp, 'rb')
              ^^^^^^^^^^^^^^
FileNotFoundError: [Errno 2] No such file or directory: 'D:\\Projects\\avatar logger\\webui\\static\\avatars\\10687465933790371852024-06-14_22-03-26.wptpyaqsut.png'
[2024-06-14 22:03:39] [ERROR   ] discord.client: Ignoring exception in on_user_update
Traceback (most recent call last):
  File "C:\Users\razzies\AppData\Local\Programs\Python\Python312\Lib\site-packages\discord\client.py", line 441, in _run_event
    await coro(*args, **kwargs)
  File "D:\Projects\avatar logger\bot\cogs\event.py", line 35, in on_user_update
    await channel.send(f"{after.mention} | `{after.name}` | `{after.id}` | <t:{int(time.time())}:R>", file=discord.File(f"{avatar_path}{fname}", fname))
                                                                                                           ^^^^^^^^^^^^^^^^^^^^^^^^^^^^^^^^^^^^^^^^^^^^
  File "C:\Users\razzies\AppData\Local\Programs\Python\Python312\Lib\site-packages\discord\file.py", line 97, in __init__
    self.fp = open(fp, 'rb')
              ^^^^^^^^^^^^^^
FileNotFoundError: [Errno 2] No such file or directory: 'D:\\Projects\\avatar logger\\webui\\static\\avatars\\10269556904823398622024-06-14_22-03-38.zjzxprydmm.png'
[2024-06-14 22:03:51] [ERROR   ] discord.client: Ignoring exception in on_user_update
Traceback (most recent call last):
  File "C:\Users\razzies\AppData\Local\Programs\Python\Python312\Lib\site-packages\discord\client.py", line 441, in _run_event
    await coro(*args, **kwargs)
  File "D:\Projects\avatar logger\bot\cogs\event.py", line 35, in on_user_update
    await channel.send(f"{after.mention} | `{after.name}` | `{after.id}` | <t:{int(time.time())}:R>", file=discord.File(f"{avatar_path}{fname}", fname))
                                                                                                           ^^^^^^^^^^^^^^^^^^^^^^^^^^^^^^^^^^^^^^^^^^^^
  File "C:\Users\razzies\AppData\Local\Programs\Python\Python312\Lib\site-packages\discord\file.py", line 97, in __init__
    self.fp = open(fp, 'rb')
              ^^^^^^^^^^^^^^
FileNotFoundError: [Errno 2] No such file or directory: 'D:\\Projects\\avatar logger\\webui\\static\\avatars\\7434126420641055342024-06-14_22-03-48.xjfhxzajgb.png'
[2024-06-14 22:04:16] [ERROR   ] discord.client: Ignoring exception in on_user_update
Traceback (most recent call last):
  File "C:\Users\razzies\AppData\Local\Programs\Python\Python312\Lib\site-packages\discord\client.py", line 441, in _run_event
    await coro(*args, **kwargs)
  File "D:\Projects\avatar logger\bot\cogs\event.py", line 35, in on_user_update
    await channel.send(f"{after.mention} | `{after.name}` | `{after.id}` | <t:{int(time.time())}:R>", file=discord.File(f"{avatar_path}{fname}", fname))
                                                                                                           ^^^^^^^^^^^^^^^^^^^^^^^^^^^^^^^^^^^^^^^^^^^^
  File "C:\Users\razzies\AppData\Local\Programs\Python\Python312\Lib\site-packages\discord\file.py", line 97, in __init__
    self.fp = open(fp, 'rb')
              ^^^^^^^^^^^^^^
FileNotFoundError: [Errno 2] No such file or directory: 'D:\\Projects\\avatar logger\\webui\\static\\avatars\\11954088062812202662024-06-14_22-04-16.byeiljgind.png'
[2024-06-14 22:04:49] [ERROR   ] discord.client: Ignoring exception in on_user_update
Traceback (most recent call last):
  File "C:\Users\razzies\AppData\Local\Programs\Python\Python312\Lib\site-packages\discord\client.py", line 441, in _run_event
    await coro(*args, **kwargs)
  File "D:\Projects\avatar logger\bot\cogs\event.py", line 35, in on_user_update
    await channel.send(f"{after.mention} | `{after.name}` | `{after.id}` | <t:{int(time.time())}:R>", file=discord.File(f"{avatar_path}{fname}", fname))
                                                                                                           ^^^^^^^^^^^^^^^^^^^^^^^^^^^^^^^^^^^^^^^^^^^^
  File "C:\Users\razzies\AppData\Local\Programs\Python\Python312\Lib\site-packages\discord\file.py", line 97, in __init__
    self.fp = open(fp, 'rb')
              ^^^^^^^^^^^^^^
FileNotFoundError: [Errno 2] No such file or directory: 'D:\\Projects\\avatar logger\\webui\\static\\avatars\\7878109241908920432024-06-14_22-04-49.bpzivlxewi.png'
[2024-06-14 22:05:48] [ERROR   ] discord.client: Ignoring exception in on_user_update
Traceback (most recent call last):
  File "C:\Users\razzies\AppData\Local\Programs\Python\Python312\Lib\site-packages\discord\client.py", line 441, in _run_event
    await coro(*args, **kwargs)
  File "D:\Projects\avatar logger\bot\cogs\event.py", line 35, in on_user_update
    await channel.send(f"{after.mention} | `{after.name}` | `{after.id}` | <t:{int(time.time())}:R>", file=discord.File(f"{avatar_path}{fname}", fname))
                                                                                                           ^^^^^^^^^^^^^^^^^^^^^^^^^^^^^^^^^^^^^^^^^^^^
  File "C:\Users\razzies\AppData\Local\Programs\Python\Python312\Lib\site-packages\discord\file.py", line 97, in __init__
    self.fp = open(fp, 'rb')
              ^^^^^^^^^^^^^^
FileNotFoundError: [Errno 2] No such file or directory: 'D:\\Projects\\avatar logger\\webui\\static\\avatars\\10269556904823398622024-06-14_22-05-48.ptnzlagvdp.png'
[2024-06-14 22:05:49] [ERROR   ] discord.client: Ignoring exception in on_user_update
Traceback (most recent call last):
  File "C:\Users\razzies\AppData\Local\Programs\Python\Python312\Lib\site-packages\discord\client.py", line 441, in _run_event
    await coro(*args, **kwargs)
  File "D:\Projects\avatar logger\bot\cogs\event.py", line 35, in on_user_update
    await channel.send(f"{after.mention} | `{after.name}` | `{after.id}` | <t:{int(time.time())}:R>", file=discord.File(f"{avatar_path}{fname}", fname))
                                                                                                           ^^^^^^^^^^^^^^^^^^^^^^^^^^^^^^^^^^^^^^^^^^^^
  File "C:\Users\razzies\AppData\Local\Programs\Python\Python312\Lib\site-packages\discord\file.py", line 97, in __init__
    self.fp = open(fp, 'rb')
              ^^^^^^^^^^^^^^
FileNotFoundError: [Errno 2] No such file or directory: 'D:\\Projects\\avatar logger\\webui\\static\\avatars\\7434126420641055342024-06-14_22-05-48.quwnnuzfpy.png'
[2024-06-14 22:06:24] [ERROR   ] discord.client: Ignoring exception in on_user_update
Traceback (most recent call last):
  File "C:\Users\razzies\AppData\Local\Programs\Python\Python312\Lib\site-packages\discord\client.py", line 441, in _run_event
    await coro(*args, **kwargs)
  File "D:\Projects\avatar logger\bot\cogs\event.py", line 35, in on_user_update
    await channel.send(f"{after.mention} | `{after.name}` | `{after.id}` | <t:{int(time.time())}:R>", file=discord.File(f"{avatar_path}{fname}", fname))
                                                                                                           ^^^^^^^^^^^^^^^^^^^^^^^^^^^^^^^^^^^^^^^^^^^^
  File "C:\Users\razzies\AppData\Local\Programs\Python\Python312\Lib\site-packages\discord\file.py", line 97, in __init__
    self.fp = open(fp, 'rb')
              ^^^^^^^^^^^^^^
FileNotFoundError: [Errno 2] No such file or directory: 'D:\\Projects\\avatar logger\\webui\\static\\avatars\\9799501350417491322024-06-14_22-06-24.xrtzbcirxs.png'
[2024-06-14 22:07:01] [ERROR   ] discord.client: Ignoring exception in on_user_update
Traceback (most recent call last):
  File "C:\Users\razzies\AppData\Local\Programs\Python\Python312\Lib\site-packages\discord\client.py", line 441, in _run_event
    await coro(*args, **kwargs)
  File "D:\Projects\avatar logger\bot\cogs\event.py", line 35, in on_user_update
    await channel.send(f"{after.mention} | `{after.name}` | `{after.id}` | <t:{int(time.time())}:R>", file=discord.File(f"{avatar_path}{fname}", fname))
                                                                                                           ^^^^^^^^^^^^^^^^^^^^^^^^^^^^^^^^^^^^^^^^^^^^
  File "C:\Users\razzies\AppData\Local\Programs\Python\Python312\Lib\site-packages\discord\file.py", line 97, in __init__
    self.fp = open(fp, 'rb')
              ^^^^^^^^^^^^^^
FileNotFoundError: [Errno 2] No such file or directory: 'D:\\Projects\\avatar logger\\webui\\static\\avatars\\7878109241908920432024-06-14_22-07-01.vrveptquph.png'
[2024-06-14 22:08:22] [ERROR   ] discord.client: Ignoring exception in on_user_update
Traceback (most recent call last):
  File "C:\Users\razzies\AppData\Local\Programs\Python\Python312\Lib\site-packages\discord\client.py", line 441, in _run_event
    await coro(*args, **kwargs)
  File "D:\Projects\avatar logger\bot\cogs\event.py", line 35, in on_user_update
    await channel.send(f"{after.mention} | `{after.name}` | `{after.id}` | <t:{int(time.time())}:R>", file=discord.File(f"{avatar_path}{fname}", fname))
                                                                                                           ^^^^^^^^^^^^^^^^^^^^^^^^^^^^^^^^^^^^^^^^^^^^
  File "C:\Users\razzies\AppData\Local\Programs\Python\Python312\Lib\site-packages\discord\file.py", line 97, in __init__
    self.fp = open(fp, 'rb')
              ^^^^^^^^^^^^^^
FileNotFoundError: [Errno 2] No such file or directory: 'D:\\Projects\\avatar logger\\webui\\static\\avatars\\8513046833848647782024-06-14_22-08-21.beprxzbvij.png'
[2024-06-14 22:12:09] [ERROR   ] discord.client: Ignoring exception in on_user_update
Traceback (most recent call last):
  File "C:\Users\razzies\AppData\Local\Programs\Python\Python312\Lib\site-packages\discord\client.py", line 441, in _run_event
    await coro(*args, **kwargs)
  File "D:\Projects\avatar logger\bot\cogs\event.py", line 35, in on_user_update
    await channel.send(f"{after.mention} | `{after.name}` | `{after.id}` | <t:{int(time.time())}:R>", file=discord.File(f"{avatar_path}{fname}", fname))
                                                                                                           ^^^^^^^^^^^^^^^^^^^^^^^^^^^^^^^^^^^^^^^^^^^^
  File "C:\Users\razzies\AppData\Local\Programs\Python\Python312\Lib\site-packages\discord\file.py", line 97, in __init__
    self.fp = open(fp, 'rb')
              ^^^^^^^^^^^^^^
FileNotFoundError: [Errno 2] No such file or directory: 'D:\\Projects\\avatar logger\\webui\\static\\avatars\\10687465933790371852024-06-14_22-12-09.ainwatlqxm.png'
[2024-06-14 22:13:49] [ERROR   ] discord.client: Ignoring exception in on_user_update
Traceback (most recent call last):
  File "C:\Users\razzies\AppData\Local\Programs\Python\Python312\Lib\site-packages\discord\client.py", line 441, in _run_event
    await coro(*args, **kwargs)
  File "D:\Projects\avatar logger\bot\cogs\event.py", line 35, in on_user_update
    await channel.send(f"{after.mention} | `{after.name}` | `{after.id}` | <t:{int(time.time())}:R>", file=discord.File(f"{avatar_path}{fname}", fname))
                                                                                                           ^^^^^^^^^^^^^^^^^^^^^^^^^^^^^^^^^^^^^^^^^^^^
  File "C:\Users\razzies\AppData\Local\Programs\Python\Python312\Lib\site-packages\discord\file.py", line 97, in __init__
    self.fp = open(fp, 'rb')
              ^^^^^^^^^^^^^^
FileNotFoundError: [Errno 2] No such file or directory: 'D:\\Projects\\avatar logger\\webui\\static\\avatars\\6446476522558586882024-06-14_22-13-48.mlqoumdyza.png'
[2024-06-14 22:15:49] [ERROR   ] discord.client: Ignoring exception in on_user_update
Traceback (most recent call last):
  File "C:\Users\razzies\AppData\Local\Programs\Python\Python312\Lib\site-packages\discord\client.py", line 441, in _run_event
    await coro(*args, **kwargs)
  File "D:\Projects\avatar logger\bot\cogs\event.py", line 35, in on_user_update
    await channel.send(f"{after.mention} | `{after.name}` | `{after.id}` | <t:{int(time.time())}:R>", file=discord.File(f"{avatar_path}{fname}", fname))
                                                                                                           ^^^^^^^^^^^^^^^^^^^^^^^^^^^^^^^^^^^^^^^^^^^^
  File "C:\Users\razzies\AppData\Local\Programs\Python\Python312\Lib\site-packages\discord\file.py", line 97, in __init__
    self.fp = open(fp, 'rb')
              ^^^^^^^^^^^^^^
FileNotFoundError: [Errno 2] No such file or directory: 'D:\\Projects\\avatar logger\\webui\\static\\avatars\\10754157510553968942024-06-14_22-15-48.ynomqrsoui.png'
[2024-06-14 22:16:00] [ERROR   ] discord.client: Ignoring exception in on_user_update
Traceback (most recent call last):
  File "C:\Users\razzies\AppData\Local\Programs\Python\Python312\Lib\site-packages\discord\client.py", line 441, in _run_event
    await coro(*args, **kwargs)
  File "D:\Projects\avatar logger\bot\cogs\event.py", line 35, in on_user_update
    await channel.send(f"{after.mention} | `{after.name}` | `{after.id}` | <t:{int(time.time())}:R>", file=discord.File(f"{avatar_path}{fname}", fname))
                                                                                                           ^^^^^^^^^^^^^^^^^^^^^^^^^^^^^^^^^^^^^^^^^^^^
  File "C:\Users\razzies\AppData\Local\Programs\Python\Python312\Lib\site-packages\discord\file.py", line 97, in __init__
    self.fp = open(fp, 'rb')
              ^^^^^^^^^^^^^^
FileNotFoundError: [Errno 2] No such file or directory: 'D:\\Projects\\avatar logger\\webui\\static\\avatars\\4433690300999270502024-06-14_22-15-59.yowdrvjmdr.png'
[2024-06-14 22:17:30] [WARNING ] discord.client: PyNaCl is not installed, voice will NOT be supported
[2024-06-14 22:17:30] [INFO    ] discord.client: logging in using static token
[2024-06-14 22:17:32] [INFO    ] discord.gateway: Shard ID None has connected to Gateway (Session ID: e0c924980c07803144542c8c60fad1bd).
[2024-06-14 22:25:02] [ERROR   ] discord.client: Ignoring exception in on_user_update
Traceback (most recent call last):
  File "C:\Users\razzies\AppData\Local\Programs\Python\Python312\Lib\site-packages\discord\client.py", line 441, in _run_event
    await coro(*args, **kwargs)
  File "D:\Projects\avatar logger\bot\cogs\event.py", line 35, in on_user_update
    await channel.send(f"{after.mention} | `{after.name}` | `{after.id}` | <t:{int(time.time())}:R>", file=discord.File(f"{avatar_path}{fname}", fname))
                                                                                                           ^^^^^^^^^^^^^^^^^^^^^^^^^^^^^^^^^^^^^^^^^^^^
  File "C:\Users\razzies\AppData\Local\Programs\Python\Python312\Lib\site-packages\discord\file.py", line 97, in __init__
    self.fp = open(fp, 'rb')
              ^^^^^^^^^^^^^^
FileNotFoundError: [Errno 2] No such file or directory: 'D:\\Projects\\avatar logger\\webui\\static\\avatars\\9884962706268160902024-06-14_22-25-02.nhcvpbowpd.png'
[2024-06-14 22:26:26] [ERROR   ] discord.client: Ignoring exception in on_user_update
Traceback (most recent call last):
  File "C:\Users\razzies\AppData\Local\Programs\Python\Python312\Lib\site-packages\discord\client.py", line 441, in _run_event
    await coro(*args, **kwargs)
  File "D:\Projects\avatar logger\bot\cogs\event.py", line 35, in on_user_update
    await channel.send(f"{after.mention} | `{after.name}` | `{after.id}` | <t:{int(time.time())}:R>", file=discord.File(f"{avatar_path}{fname}", fname))
                                                                                                           ^^^^^^^^^^^^^^^^^^^^^^^^^^^^^^^^^^^^^^^^^^^^
  File "C:\Users\razzies\AppData\Local\Programs\Python\Python312\Lib\site-packages\discord\file.py", line 97, in __init__
    self.fp = open(fp, 'rb')
              ^^^^^^^^^^^^^^
FileNotFoundError: [Errno 2] No such file or directory: 'D:\\Projects\\avatar logger\\webui\\static\\avatars\\8978940451064709532024-06-14_22-26-25.eudtgbbxcv.png'
[2024-06-14 22:27:32] [ERROR   ] discord.client: Ignoring exception in on_user_update
Traceback (most recent call last):
  File "C:\Users\razzies\AppData\Local\Programs\Python\Python312\Lib\site-packages\discord\client.py", line 441, in _run_event
    await coro(*args, **kwargs)
  File "D:\Projects\avatar logger\bot\cogs\event.py", line 35, in on_user_update
    await channel.send(f"{after.mention} | `{after.name}` | `{after.id}` | <t:{int(time.time())}:R>", file=discord.File(f"{avatar_path}{fname}", fname))
                                                                                                           ^^^^^^^^^^^^^^^^^^^^^^^^^^^^^^^^^^^^^^^^^^^^
  File "C:\Users\razzies\AppData\Local\Programs\Python\Python312\Lib\site-packages\discord\file.py", line 97, in __init__
    self.fp = open(fp, 'rb')
              ^^^^^^^^^^^^^^
FileNotFoundError: [Errno 2] No such file or directory: 'D:\\Projects\\avatar logger\\webui\\static\\avatars\\10687465933790371852024-06-14_22-27-32.qxemxpmsah.png'
[2024-06-14 22:28:58] [ERROR   ] discord.client: Ignoring exception in on_user_update
Traceback (most recent call last):
  File "C:\Users\razzies\AppData\Local\Programs\Python\Python312\Lib\site-packages\discord\client.py", line 441, in _run_event
    await coro(*args, **kwargs)
  File "D:\Projects\avatar logger\bot\cogs\event.py", line 35, in on_user_update
    await channel.send(f"{after.mention} | `{after.name}` | `{after.id}` | <t:{int(time.time())}:R>", file=discord.File(f"{avatar_path}{fname}", fname))
                                                                                                           ^^^^^^^^^^^^^^^^^^^^^^^^^^^^^^^^^^^^^^^^^^^^
  File "C:\Users\razzies\AppData\Local\Programs\Python\Python312\Lib\site-packages\discord\file.py", line 97, in __init__
    self.fp = open(fp, 'rb')
              ^^^^^^^^^^^^^^
FileNotFoundError: [Errno 2] No such file or directory: 'D:\\Projects\\avatar logger\\webui\\static\\avatars\\10687465933790371852024-06-14_22-28-57.mirecohbrk.png'
[2024-06-14 22:29:55] [ERROR   ] discord.client: Ignoring exception in on_user_update
Traceback (most recent call last):
  File "C:\Users\razzies\AppData\Local\Programs\Python\Python312\Lib\site-packages\discord\client.py", line 441, in _run_event
    await coro(*args, **kwargs)
  File "D:\Projects\avatar logger\bot\cogs\event.py", line 35, in on_user_update
    await channel.send(f"{after.mention} | `{after.name}` | `{after.id}` | <t:{int(time.time())}:R>", file=discord.File(f"{avatar_path}{fname}", fname))
                                                                                                           ^^^^^^^^^^^^^^^^^^^^^^^^^^^^^^^^^^^^^^^^^^^^
  File "C:\Users\razzies\AppData\Local\Programs\Python\Python312\Lib\site-packages\discord\file.py", line 97, in __init__
    self.fp = open(fp, 'rb')
              ^^^^^^^^^^^^^^
FileNotFoundError: [Errno 2] No such file or directory: 'D:\\Projects\\avatar logger\\webui\\static\\avatars\\11734137966231757402024-06-14_22-29-54.apqywkhuqh.png'
[2024-06-14 22:30:12] [ERROR   ] discord.client: Ignoring exception in on_user_update
Traceback (most recent call last):
  File "C:\Users\razzies\AppData\Local\Programs\Python\Python312\Lib\site-packages\discord\client.py", line 441, in _run_event
    await coro(*args, **kwargs)
  File "D:\Projects\avatar logger\bot\cogs\event.py", line 35, in on_user_update
    await channel.send(f"{after.mention} | `{after.name}` | `{after.id}` | <t:{int(time.time())}:R>", file=discord.File(f"{avatar_path}{fname}", fname))
                                                                                                           ^^^^^^^^^^^^^^^^^^^^^^^^^^^^^^^^^^^^^^^^^^^^
  File "C:\Users\razzies\AppData\Local\Programs\Python\Python312\Lib\site-packages\discord\file.py", line 97, in __init__
    self.fp = open(fp, 'rb')
              ^^^^^^^^^^^^^^
FileNotFoundError: [Errno 2] No such file or directory: 'D:\\Projects\\avatar logger\\webui\\static\\avatars\\6942177121211516012024-06-14_22-30-11.pvtiksnglx.png'
[2024-06-14 22:32:59] [ERROR   ] discord.client: Ignoring exception in on_user_update
Traceback (most recent call last):
  File "C:\Users\razzies\AppData\Local\Programs\Python\Python312\Lib\site-packages\discord\client.py", line 441, in _run_event
    await coro(*args, **kwargs)
  File "D:\Projects\avatar logger\bot\cogs\event.py", line 35, in on_user_update
    await channel.send(f"{after.mention} | `{after.name}` | `{after.id}` | <t:{int(time.time())}:R>", file=discord.File(f"{avatar_path}{fname}", fname))
                                                                                                           ^^^^^^^^^^^^^^^^^^^^^^^^^^^^^^^^^^^^^^^^^^^^
  File "C:\Users\razzies\AppData\Local\Programs\Python\Python312\Lib\site-packages\discord\file.py", line 97, in __init__
    self.fp = open(fp, 'rb')
              ^^^^^^^^^^^^^^
FileNotFoundError: [Errno 2] No such file or directory: 'D:\\Projects\\avatar logger\\webui\\static\\avatars\\5301503538663260272024-06-14_22-32-59.ibpprijaxr.png'
[2024-06-14 22:34:37] [ERROR   ] discord.client: Ignoring exception in on_user_update
Traceback (most recent call last):
  File "C:\Users\razzies\AppData\Local\Programs\Python\Python312\Lib\site-packages\discord\client.py", line 441, in _run_event
    await coro(*args, **kwargs)
  File "D:\Projects\avatar logger\bot\cogs\event.py", line 35, in on_user_update
    await channel.send(f"{after.mention} | `{after.name}` | `{after.id}` | <t:{int(time.time())}:R>", file=discord.File(f"{avatar_path}{fname}", fname))
                                                                                                           ^^^^^^^^^^^^^^^^^^^^^^^^^^^^^^^^^^^^^^^^^^^^
  File "C:\Users\razzies\AppData\Local\Programs\Python\Python312\Lib\site-packages\discord\file.py", line 97, in __init__
    self.fp = open(fp, 'rb')
              ^^^^^^^^^^^^^^
FileNotFoundError: [Errno 2] No such file or directory: 'D:\\Projects\\avatar logger\\webui\\static\\avatars\\11734137966231757402024-06-14_22-34-37.tolrduafrn.png'
[2024-06-14 22:34:48] [ERROR   ] discord.client: Ignoring exception in on_user_update
Traceback (most recent call last):
  File "C:\Users\razzies\AppData\Local\Programs\Python\Python312\Lib\site-packages\discord\client.py", line 441, in _run_event
    await coro(*args, **kwargs)
  File "D:\Projects\avatar logger\bot\cogs\event.py", line 35, in on_user_update
    await channel.send(f"{after.mention} | `{after.name}` | `{after.id}` | <t:{int(time.time())}:R>", file=discord.File(f"{avatar_path}{fname}", fname))
                                                                                                           ^^^^^^^^^^^^^^^^^^^^^^^^^^^^^^^^^^^^^^^^^^^^
  File "C:\Users\razzies\AppData\Local\Programs\Python\Python312\Lib\site-packages\discord\file.py", line 97, in __init__
    self.fp = open(fp, 'rb')
              ^^^^^^^^^^^^^^
FileNotFoundError: [Errno 2] No such file or directory: 'D:\\Projects\\avatar logger\\webui\\static\\avatars\\4224498721766768752024-06-14_22-34-47.bswjaazhpu.png'
[2024-06-14 22:39:04] [ERROR   ] discord.client: Ignoring exception in on_user_update
Traceback (most recent call last):
  File "C:\Users\razzies\AppData\Local\Programs\Python\Python312\Lib\site-packages\discord\client.py", line 441, in _run_event
    await coro(*args, **kwargs)
  File "D:\Projects\avatar logger\bot\cogs\event.py", line 35, in on_user_update
    await channel.send(f"{after.mention} | `{after.name}` | `{after.id}` | <t:{int(time.time())}:R>", file=discord.File(f"{avatar_path}{fname}", fname))
                                                                                                           ^^^^^^^^^^^^^^^^^^^^^^^^^^^^^^^^^^^^^^^^^^^^
  File "C:\Users\razzies\AppData\Local\Programs\Python\Python312\Lib\site-packages\discord\file.py", line 97, in __init__
    self.fp = open(fp, 'rb')
              ^^^^^^^^^^^^^^
FileNotFoundError: [Errno 2] No such file or directory: 'D:\\Projects\\avatar logger\\webui\\static\\avatars\\10687465933790371852024-06-14_22-39-04.lnscikaexc.png'
[2024-06-14 22:47:22] [ERROR   ] discord.client: Ignoring exception in on_user_update
Traceback (most recent call last):
  File "C:\Users\razzies\AppData\Local\Programs\Python\Python312\Lib\site-packages\discord\client.py", line 441, in _run_event
    await coro(*args, **kwargs)
  File "D:\Projects\avatar logger\bot\cogs\event.py", line 35, in on_user_update
    await channel.send(f"{after.mention} | `{after.name}` | `{after.id}` | <t:{int(time.time())}:R>", file=discord.File(f"{avatar_path}{fname}", fname))
                                                                                                           ^^^^^^^^^^^^^^^^^^^^^^^^^^^^^^^^^^^^^^^^^^^^
  File "C:\Users\razzies\AppData\Local\Programs\Python\Python312\Lib\site-packages\discord\file.py", line 97, in __init__
    self.fp = open(fp, 'rb')
              ^^^^^^^^^^^^^^
FileNotFoundError: [Errno 2] No such file or directory: 'D:\\Projects\\avatar logger\\webui\\static\\avatars\\6446476522558586882024-06-14_22-47-17.gklgyrxofv.png'
[2024-06-14 22:47:27] [ERROR   ] discord.client: Ignoring exception in on_user_update
Traceback (most recent call last):
  File "C:\Users\razzies\AppData\Local\Programs\Python\Python312\Lib\site-packages\discord\client.py", line 441, in _run_event
    await coro(*args, **kwargs)
  File "D:\Projects\avatar logger\bot\cogs\event.py", line 35, in on_user_update
    await channel.send(f"{after.mention} | `{after.name}` | `{after.id}` | <t:{int(time.time())}:R>", file=discord.File(f"{avatar_path}{fname}", fname))
                                                                                                           ^^^^^^^^^^^^^^^^^^^^^^^^^^^^^^^^^^^^^^^^^^^^
  File "C:\Users\razzies\AppData\Local\Programs\Python\Python312\Lib\site-packages\discord\file.py", line 97, in __init__
    self.fp = open(fp, 'rb')
              ^^^^^^^^^^^^^^
FileNotFoundError: [Errno 2] No such file or directory: 'D:\\Projects\\avatar logger\\webui\\static\\avatars\\10913844494233927982024-06-14_22-47-27.zskfzwhuaj.png'
[2024-06-14 22:48:49] [ERROR   ] discord.client: Ignoring exception in on_user_update
Traceback (most recent call last):
  File "C:\Users\razzies\AppData\Local\Programs\Python\Python312\Lib\site-packages\discord\client.py", line 441, in _run_event
    await coro(*args, **kwargs)
  File "D:\Projects\avatar logger\bot\cogs\event.py", line 35, in on_user_update
    await channel.send(f"{after.mention} | `{after.name}` | `{after.id}` | <t:{int(time.time())}:R>", file=discord.File(f"{avatar_path}{fname}", fname))
                                                                                                           ^^^^^^^^^^^^^^^^^^^^^^^^^^^^^^^^^^^^^^^^^^^^
  File "C:\Users\razzies\AppData\Local\Programs\Python\Python312\Lib\site-packages\discord\file.py", line 97, in __init__
    self.fp = open(fp, 'rb')
              ^^^^^^^^^^^^^^
FileNotFoundError: [Errno 2] No such file or directory: 'D:\\Projects\\avatar logger\\webui\\static\\avatars\\10913844494233927982024-06-14_22-48-49.skfyklieed.png'
[2024-06-14 22:49:43] [ERROR   ] discord.client: Ignoring exception in on_user_update
Traceback (most recent call last):
  File "C:\Users\razzies\AppData\Local\Programs\Python\Python312\Lib\site-packages\discord\client.py", line 441, in _run_event
    await coro(*args, **kwargs)
  File "D:\Projects\avatar logger\bot\cogs\event.py", line 35, in on_user_update
    await channel.send(f"{after.mention} | `{after.name}` | `{after.id}` | <t:{int(time.time())}:R>", file=discord.File(f"{avatar_path}{fname}", fname))
                                                                                                           ^^^^^^^^^^^^^^^^^^^^^^^^^^^^^^^^^^^^^^^^^^^^
  File "C:\Users\razzies\AppData\Local\Programs\Python\Python312\Lib\site-packages\discord\file.py", line 97, in __init__
    self.fp = open(fp, 'rb')
              ^^^^^^^^^^^^^^
FileNotFoundError: [Errno 2] No such file or directory: 'D:\\Projects\\avatar logger\\webui\\static\\avatars\\5406209249830502602024-06-14_22-49-42.icezxranjw.png'
